// used to next the error thrown by controllers - this way we can avoid try and catch block

const catchAsync = (fn) => (req, res, next) => {
  Promise.resolve(fn(req, res, next)).catch((err) => next(err));
};

module.exports = catchAsync;
